Workbook

Sheet Examen
E1: Nota (/1) | F1: Factor
A2: =(B2+B22)/2 | B2: =(E2+E8+E10+E12+E16+E19)/6 | C2: Operativo | D2: (¿cómo se gana dinero hoy?) | E2: =((SUM(H2:H7)/COUNT(H2:H7))/3)*10 | F2: ¿Tiene la empresa un monopolio del consumidor fácilmente identificable? | H2: =IF(G2="Marca conocida pero con competencia",1,IF(G2="Marca conocida y poca competencia",2,IF(G2="Marca conocida con clientes cautivos (barreras de salida)",3,0)))
F3: ¿Es el I+D fundamental para el crecimiento? | H3: =IF(G3="Totalmente esencial",1,IF(G3="Necesario para mantenerse",2,IF(G3="No esencial pero aporta valor",3,0)))
F4: ¿Puede ajustar precios según la inflación? | H4: =IF(G4="No, compite por precio",1,IF(G4="Limitadamente",2,IF(G4="Sí, total pricing power",3,0)))
F5: ¿Tiene poder de compra frente a proveedores? | H5: =IF(G5="No, proveedores dominantes",1,IF(G5="Tiene alternativas pero sin poder de negociación",2,IF(G5="Sí, fuerte poder de compra",3,0)))
F6: ¿Tiene poder de fijación de precios frente a clientes? | H6: =IF(G6="No, clientes dominan",1,IF(G6="Sí, por diferenciación",2,IF(G6="Sí, casi sin competencia",3,0)))
F7: ¿Existen productos sustitutivos en recesión? | H7: =IF(G7="Sí, muchos",1,IF(G7="Algunos pero diferenciados",2,IF(G7="No, valor añadido muy alto",3,0)))
C8: Producto | D8: (¿hay futuro?) | E8: =((SUM(H8:H9)/COUNT(H8:H9)/3)*10) | F8: ¿Ofrece la empresa productos o servicios con el suficiente potencial comercial como para hacer posible un incremento considerable de las ventas durante al menos varios años? | H8: =IF(G8="No, los productos actuales están llegando a su madurez.",1,IF(G8="Sí, pero requieren innovación o expansión geográfica para sostener el crecimiento.",2,IF(G8="Sí, los productos tienen largo recorrido y existen nuevas categorías con potencial.",3,0)))
F9: ¿Está la dirección decidida a desarrollar productos o procesos que sigan aumentando las ventas cuando las líneas actuales se saturen? | H9: =IF(G9="No, la empresa se apoya en su catálogo actual sin un plan claro de innovación.",1,IF(G9="Moderadamente, hay nuevos proyectos pero sin una estrategia definida.",2,IF(G9="Sí, existe una política activa de desarrollo continuo de nuevos productos y procesos.",3,0)))
C10: Dirección | D10: (¿se puede confiar en quien ejecuta?) | E10: =((SUM(H10:H11)/COUNT(H10:H11)/3)*10) | F10: ¿Cuánto tiempo llevan los directores en la compañía? ¿Existe un líder clave? | H10: =IF(G10="Alta rotación o liderazgo inestable.",1,IF(G10="Equipo con cierta continuidad pero sin Massia",2,IF(G10="Dirección estable, con liderazgo claro y trayectoria demostrada In-house.",3,0)))
F11: ¿Tiene la empresa un equipo directivo con una integridad incuestionable, transparencia y velando por los accionistas? | H11: =IF(G11="Dudas sobre la transparencia o el gobierno corporativo.",1,IF(G11="Integridad razonable pero con áreas mejorables.",2,IF(G11="Alta integridad y alineación con los accionistas.",3,0)))
C12: Estrategia | D12: (¿tiene plan para escalar?) | E12: =((((SUM(H12:H15)/4))/3)*10) | F12: ¿Es la estrategia de marketing vital, innovadora y efectiva para el negocio? | H12: =IF(G12="Estrategia convencional, sin diferenciación.",1,IF(G12="Estrategia sólida pero poco innovadora.",2,IF(G12="Estrategia claramente diferenciada e innovadora, con impacto demostrado.",3,0)))
F13: ¿Previsión a corto o a largo plazo en relación con los beneficios? | H13: =IF(G13="Enfoque cortoplacista, centrado en resultados inmediatos.",1,IF(G13="Combina visión a corto y largo plazo sin una hoja de ruta clara.",2,IF(G13="Estrategia orientada al largo plazo, con objetivos definidos y consistentes.",3,0)))
F14: ¿Requerirá el crecimiento futuro de la empresa nuevas ampliaciones de capital? | H14: =IF(G14="Sí, el crecimiento depende de financiación externa o emisiones.",1,IF(G14="Puede requerir financiación puntual o deuda moderada.",2,IF(G14="No, el crecimiento es autofinanciado mediante generación de caja.",3,0)))
F15: ¿Han sido capaces de cumplir con objetivos pasados? | H15: =IF(G15="No, y no han rectificado expectativas",1,IF(G15="Se han quedado cerca, analizado el motivo y rectificado",2,IF(G15="Si, cumplen su plan de crecimiento.",3,0)))
C16: Valores y cultura | D16: (¿la empresa puede perdurar con su cultura?) | E16: =((((SUM(H16:H18)/3))/3)*10) | F16: ¿Son los valores corporativos auténticos o una simple herramienta de marketing? | H16: =IF(G16="Valores principalmente cosméticos o inconsistentes con las acciones.",1,IF(G16="Mezcla de comunicación y realidad empresarial.",2,IF(G16="Valores auténticos e integrados en la cultura corporativa.",3,0)))
F17: ¿Se preocupa la empresa por sus trabajadores? | H17: =IF(G17="Alta rotación o mala reputación laboral.",1,IF(G17="Políticas laborales aceptables pero sin programas destacados.",2,IF(G17="Alta satisfacción, retención y desarrollo interno del talento.",3,0)))
F18: ¿Busca la empresa equilibrar rentabilidad económica y beneficio social? | H18: =IF(G18="Enfocada únicamente en el beneficio financiero.",1,IF(G18="Tiene iniciativas sociales puntuales sin impacto significativo.",2,IF(G18="Integra sostenibilidad y propósito social en su modelo de negocio.",3,0)))
C19: Sector y posicionamiento | D19: (¿el viento sopla a favor?) | E19: =(((SUM(H19:H21)/3))/3)*10 | F19: ¿Existen barreras de entrada o ventajas competitivas estructurales en su sector? | H19: =IF(G19="Mercado abierto, fácil entrada de competidores.",1,IF(G19="Algunas barreras, principalmente de marca o distribución.",2,IF(G19="Altas barreras tecnológicas, de marca o capital intensivo.",3,0)))
F20: ¿Por qué es mejor que la competencia? | H20: =IF(G20="Tiene ventajas parciales, pero comparables a sus rivales.",1,IF(G20="Posee ventajas sostenibles y diferenciales claras frente a la competencia.",2,IF(G20="No tiene competencia comparable.",3,0)))
F21: ¿Es un sector intensivo en capital? (CAPEX) | H21: =IF(G21="Sí, requiere inversión constante",1,IF(G21="Moderado",2,IF(G21="No, depende de conocimiento o creatividad",3,0)))
B22: =(E22+E28+E39)/3 | C22: PyG | E22: =(((SUM(H22:H27)/6))*10)/3 | F22: Calidad del crecimiento de ingresos | H22: =IF(G22="Crecimiento errático, cíclico o puntual",1,IF(G22="Crecimiento relativamente estable, con componentes estructurales y coyunturales",2,IF(G22="Crecimiento consistente, orgánico y apoyado en demanda recurrente o clara expansión de mercado.",3,0)))
F23: Defensabilidad del margen bruto | H23: =IF(G23="Margen presionable",1,IF(G23="Margen razonable",2,IF(G23="Margen defensable",3,0)))
F24: Flexibilidad de la estructura de costes | H24: =IF(G24="Costes rígidos",1,IF(G24="Costes mixtos",2,IF(G24="Costes flexibles",3,0)))
F25: Margen de beneficio neto | H25: =IF(G25="Margen neto < 15%",1,IF(G25="Margen neto entre 15% y 30%",2,IF(G25="Margen neto > 30%",3,0)))
F26: Dependencia financiera y fiscal | H26: =IF(G26="Alta dependencia",1,IF(G26="Dependencia moderada",2,IF(G26="Baja dependencia",3,0)))
F27: Consistencia del beneficio neto | H27: =IF(G27="Beneficio volátil",1,IF(G27="Beneficio estable",2,IF(G27="Beneficio recurrente",3,0)))
C28: Balance | E28: =(((SUM(H28:H38)/11))*10)/3 | F28: Evolución del efectivo y equivalentes | H28: =IF(G28="Disminuye",1,IF(G28="Se mantiene",2,IF(G28="Aumenta",3,0)))
F29: Deuda ajustada / Equity | H29: =IF(G29="Mayor a 0,8",1,IF(G29="Entre 0,6 y 0,8",2,IF(G29="Menor a 0,6",3,0)))
F30: Existencias vs crecimiento de ingresos | H30: =IF(G30="Desalineadas o muy cíclicas",1,IF(G30="Ligera acumulación",2,IF(G30="Alineadas con el crecimiento",3,0)))
F31: Clientes / ventas anuales | H31: =IF(G31="Mayor al 30%",1,IF(G31="Entre 15% y 30%",2,IF(G31="Menor al 15%",3,0)))
F32: Inmovilizado (PPE) sobre activo | H32: =IF(G32="Mayor al 40%",1,IF(G32="Entre 20% y 40%",2,IF(G32="Menor al 20%",3,0)))
F33: Liquidez operativa vs pasivo corriente | H33: =IF(G33="OCF insuficiente",1,IF(G33="Cobertura parcial",2,IF(G33="Cobertura holgada",3,0)))
F34: Repago deuda corto plazo con OCF | H34: =IF(G34="Más de 2 años",1,IF(G34="Entre 1 y 2 años",2,IF(G34="Menos de 1 año",3,0)))
F35: Repago deuda largo plazo con OCF | H35: =IF(G35="Más de 5 años",1,IF(G35="Entre 3 y 5 años",2,IF(G35="Menos de 3 años",3,0)))
F36: Tendencia del coeficiente de solvencia (5 años) | H36: =IF(G36="Empeora",1,IF(G36="Se mantiene",2,IF(G36="Mejora",3,0)))
F37: Política de capital (acciones propias) | H37: =IF(G37="Emite acciones",1,IF(G37="Ni emite ni recompra",2,IF(G37="Recompra acciones",3,0)))
F38: ROE | H38: =IF(G38="Menor al 15%",1,IF(G38="Entre 15% y 25%",2,IF(G38="Mayor al 25%",3,0)))
C39: Cash Flow | E39: =(((SUM(H39:H44)/6))*10)/3 | F39: Flujo operativo vs beneficio neto | H39: =IF(G39="Menor que el beneficio neto",1,IF(G39="Similar al beneficio neto",2,IF(G39="Mayor que el beneficio neto",3,0)))
F40: CAGR del flujo operativo vs CAGR del beneficio neto | H40: =IF(G40="Menor",1,IF(G40="Similar",2,IF(G40="Mayor",3,0)))
...

Sheet Modelo EPS
B1: AÑO | C1: precio | D1: Incremento | E1: EPS | F1: Incremento | G1: Rentabilidad anual | H1: PER | I1: Dividendo por acción | J1: % dividendos sobre B | K1: Reservas | L1: % reservas sobre B | M1: ingresos (milion) | N1: Incremento | O1: beneficios (bilion) | Q1: margen beneficio | R1: Incremento | S1: Acciones | T1: Book value per share | U1: Incremento | V1: ROE | W1: Histórico (2016-2025) / Proyectado con escenario Base (2026-2035)
B2: =B3-1 | C2: 97.33 | E2: =PyG!D29 | G2: =E2/C2 | H2: =C2/E2 | I2: =ABS('Cash Flow'!D29)/S2 | J2: =(I2/E2) | K2: =E2-I2 | L2: =K2/E2 | M2: =PyG!D8 | O2: =PyG!D23 | Q2: =O2/M2 | S2: =PyG!D27 | T2: =Balance!D26/'Modelo EPS'!S2 | V2: =O2/(T2*S2)
B3: =B4-1 | C3: 138.71 | D3: =(C3-C2)/C2 | E3: =PyG!E29 | F3: =(E3-E2)/E2 | G3: =E3/C3 | H3: =C3/E3 | I3: =ABS('Cash Flow'!E29)/S3 | J3: =(I3/E3) | K3: =E3-I3 | L3: =K3/E3 | M3: =PyG!E8 | N3: =(M3-M2)/M2 | O3: =PyG!E23 | P3: =(O3-O2)/O2 | Q3: =O3/M3 | R3: =(O3-O2)/O2 | S3: =PyG!E27 | T3: =Balance!E26/'Modelo EPS'!S3 | U3: =(T3-T2)/T2 | V3: =O3/(T3*S3)
B4: =B5-1 | C4: 230.67 | D4: =(C4-C3)/C3 | E4: =PyG!F29 | F4: =(E4-E3)/E3 | G4: =E4/C4 | H4: =C4/E4 | I4: =ABS('Cash Flow'!F29)/S4 | J4: =(I4/E4) | K4: =E4-I4 | L4: =K4/E4 | M4: =PyG!F8 | N4: =(M4-M3)/M3 | O4: =PyG!F23 | P4: =(O4-O3)/O3 | Q4: =O4/M4 | R4: =(O4-O3)/O3 | S4: =PyG!F27 | T4: =Balance!F26/'Modelo EPS'!S4 | U4: =(T4-T3)/T3 | V4: =O4/(T4*S4)
B5: =B6-1 | C5: 272.53 | D5: =(C5-C4)/C4 | E5: =PyG!G29 | F5: =(E5-E4)/E4 | G5: =E5/C5 | H5: =C5/E5 | I5: =ABS('Cash Flow'!G29)/S5 | J5: =(I5/E5) | K5: =E5-I5 | L5: =K5/E5 | M5: =PyG!G8 | N5: =(M5-M4)/M4 | O5: =PyG!G23 | P5: =(O5-O4)/O4 | Q5: =O5/M5 | R5: =(O5-O4)/O4 | S5: =PyG!G27 | T5: =Balance!G26/'Modelo EPS'!S5 | U5: =(T5-T4)/T4 | V5: =O5/(T5*S5)
B6: =B7-1 | C6: 400.85 | D6: =(C6-C5)/C5 | E6: =PyG!H29 | F6: =(E6-E5)/E5 | G6: =E6/C6 | H6: =C6/E6 | I6: =ABS('Cash Flow'!H29)/S6 | J6: =(I6/E6) | K6: =E6-I6 | L6: =K6/E6 | M6: =PyG!H8 | N6: =(M6-M5)/M5 | O6: =PyG!H23 | P6: =(O6-O5)/O5 | Q6: =O6/M6 | R6: =(O6-O5)/O5 | S6: =PyG!H27 | T6: =Balance!H26/'Modelo EPS'!S6 | U6: =(T6-T5)/T5 | V6: =O6/(T6*S6)
B7: =B8-1 | C7: 551.68 | D7: =(C7-C6)/C6 | E7: =PyG!I29 | F7: =(E7-E6)/E6 | G7: =E7/C7 | H7: =C7/E7 | I7: =ABS('Cash Flow'!I29)/S7 | J7: =(I7/E7) | K7: =E7-I7 | L7: =K7/E7 | M7: =PyG!I8 | N7: =(M7-M6)/M6 | O7: =PyG!I23 | P7: =(O7-O6)/O6 | Q7: =O7/M7 | R7: =(O7-O6)/O6 | S7: =PyG!I27 | T7: =Balance!I26/'Modelo EPS'!S7 | U7: =(T7-T6)/T6 | V7: =O7/(T7*S7)
B8: =B9-1 | C8: 415.92 | D8: =(C8-C7)/C7 | E8: =PyG!J29 | F8: =(E8-E7)/E7 | G8: =E8/C8 | H8: =C8/E8 | I8: =ABS('Cash Flow'!J29)/S8 | J8: =(I8/E8) | K8: =E8-I8 | L8: =K8/E8 | M8: =PyG!J8 | N8: =(M8-M7)/M7 | O8: =PyG!J23 | P8: =(O8-O7)/O7 | Q8: =O8/M8 | R8: =(O8-O7)/O7 | S8: =PyG!J27 | T8: =Balance!J26/'Modelo EPS'!S8 | U8: =(T8-T7)/T7 | V8: =O8/(T8*S8)
B9: =B10-1 | C9: 445.22 | D9: =(C9-C8)/C8 | E9: =PyG!K29 | F9: =(E9-E8)/E8 | G9: =E9/C9 | H9: =C9/E9 | I9: =ABS('Cash Flow'!K29)/S9 | J9: =(I9/E9) | K9: =E9-I9 | L9: =K9/E9 | M9: =PyG!K8 | N9: =(M9-M8)/M8 | O9: =PyG!K23 | P9: =(O9-O8)/O8 | Q9: =O9/M9 | R9: =(O9-O8)/O8 | S9: =PyG!K27 | T9: =Balance!K26/'Modelo EPS'!S9 | U9: =(T9-T8)/T8 | V9: =O9/(T9*S9)
B10: =B11-1 | C10: 534.2 | D10: =(C10-C9)/C9 | E10: =PyG!L29 | F10: =(E10-E9)/E9 | G10: =E10/C10 | H10: =C10/E10 | I10: =ABS('Cash Flow'!L29)/S10 | J10: =(I10/E10) | K10: =E10-I10 | L10: =K10/E10 | M10: =PyG!L8 | N10: =(M10-M9)/M9 | O10: =PyG!L23 | P10: =(O10-O9)/O9 | Q10: =O10/M10 | R10: =(O10-O9)/O9 | S10: =PyG!L27 | T10: =Balance!L26/'Modelo EPS'!S10 | U10: =(T10-T9)/T9 | V10: =O10/(T10*S10)
B11: =B12-1 | C11: 389.14 | D11: =(C11-C10)/C10 | E11: =PyG!M29 | F11: =(E11-E10)/E10 | G11: =E11/C11 | H11: =C11/E11 | I11: =ABS('Cash Flow'!M29)/S11 | J11: =(I11/E11) | K11: =E11-I11 | L11: =K11/E11 | M11: =PyG!M8 | N11: =(M11-M10)/M10 | O11: =PyG!M23 | P11: =(O11-O10)/O10 | Q11: =O11/M11 | R11: =(O11-O10)/O10 | S11: =PyG!M27 | T11: =Balance!M26/'Modelo EPS'!S11 | U11: =(T11-T10)/T10 | V11: =O11/(T11*S11)
B12: =B13-1 | E12: ='Proy. Base'!D25 | F12: =(E12-E11)/E11 | I12: ='Proy. Base'!D27 | J12: =(I12/E12) | K12: =E12-I12 | L12: =K12/E12 | M12: ='Proy. Base'!D8 | N12: =(M12-M11)/M11 | O12: ='Proy. Base'!D22 | P12: =(O12-O11)/O11 | Q12: =O12/M12 | R12: =(O12-O11)/O11 | S12: ='Proy. Base'!D24 | T12: ='Proy. Base'!D59 | U12: =(T12-T11)/T11 | V12: ='Proy. Base'!D58
B13: =B14-1 | E13: ='Proy. Base'!E25 | F13: =(E13-E12)/E12 | I13: ='Proy. Base'!E27 | J13: =(I13/E13) | K13: =E13-I13 | L13: =K13/E13 | M13: ='Proy. Base'!E8 | N13: =(M13-M12)/M12 | O13: ='Proy. Base'!E22 | P13: =(O13-O12)/O12 | Q13: =O13/M13 | R13: =(O13-O12)/O12 | S13: ='Proy. Base'!E24 | T13: ='Proy. Base'!E59 | U13: =(T13-T12)/T12 | V13: ='Proy. Base'!E58
B14: =B15-1 | E14: ='Proy. Base'!F25 | F14: =(E14-E13)/E13 | I14: ='Proy. Base'!F27 | J14: =(I14/E14) | K14: =E14-I14 | L14: =K14/E14 | M14: ='Proy. Base'!F8 | N14: =(M14-M13)/M13 | O14: ='Proy. Base'!F22 | P14: =(O14-O13)/O13 | Q14: =O14/M14 | R14: =(O14-O13)/O13 | S14: ='Proy. Base'!F24 | T14: ='Proy. Base'!F59 | U14: =(T14-T13)/T13 | V14: ='Proy. Base'!F58
B15: =B16-1 | E15: ='Proy. Base'!G25 | F15: =(E15-E14)/E14 | I15: ='Proy. Base'!G27 | J15: =(I15/E15) | K15: =E15-I15 | L15: =K15/E15 | M15: ='Proy. Base'!G8 | N15: =(M15-M14)/M14 | O15: ='Proy. Base'!G22 | P15: =(O15-O14)/O14 | Q15: =O15/M15 | R15: =(O15-O14)/O14 | S15: ='Proy. Base'!G24 | T15: ='Proy. Base'!G59 | U15: =(T15-T14)/T14 | V15: ='Proy. Base'!G58
B16: =B17-1 | E16: ='Proy. Base'!H25 | F16: =(E16-E15)/E15 | I16: ='Proy. Base'!H27 | J16: =(I16/E16) | K16: =E16-I16 | L16: =K16/E16 | M16: ='Proy. Base'!H8 | N16: =(M16-M15)/M15 | O16: ='Proy. Base'!H22 | P16: =(O16-O15)/O15 | Q16: =O16/M16 | R16: =(O16-O15)/O15 | S16: ='Proy. Base'!H24 | T16: ='Proy. Base'!H59 | U16: =(T16-T15)/T15 | V16: ='Proy. Base'!H58
B17: =B18-1 | E17: ='Proy. Base'!I25 | F17: =(E17-E16)/E16 | I17: ='Proy. Base'!I27 | J17: =(I17/E17) | K17: =E17-I17 | L17: =K17/E17 | M17: ='Proy. Base'!I8 | N17: =(M17-M16)/M16 | O17: ='Proy. Base'!I22 | P17: =(O17-O16)/O16 | Q17: =O17/M17 | R17: =(O17-O16)/O16 | S17: ='Proy. Base'!I24 | T17: ='Proy. Base'!I59 | U17: =(T17-T16)/T16 | V17: ='Proy. Base'!I58
B18: =B19-1 | E18: ='Proy. Base'!J25 | F18: =(E18-E17)/E17 | I18: ='Proy. Base'!J27 | J18: =(I18/E18) | K18: =E18-I18 | L18: =K18/E18 | M18: ='Proy. Base'!J8 | N18: =(M18-M17)/M17 | O18: ='Proy. Base'!J22 | P18: =(O18-O17)/O17 | Q18: =O18/M18 | R18: =(O18-O17)/O17 | S18: ='Proy. Base'!J24 | T18: ='Proy. Base'!J59 | U18: =(T18-T17)/T17 | V18: ='Proy. Base'!J58
B19: =B20-1 | E19: ='Proy. Base'!K25 | F19: =(E19-E18)/E18 | I19: ='Proy. Base'!K27 | J19: =(I19/E19) | K19: =E19-I19 | L19: =K19/E19 | M19: ='Proy. Base'!K8 | N19: =(M19-M18)/M18 | O19: ='Proy. Base'!K22 | P19: =(O19-O18)/O18 | Q19: =O19/M19 | R19: =(O19-O18)/O18 | S19: ='Proy. Base'!K24 | T19: ='Proy. Base'!K59 | U19: =(T19-T18)/T18 | V19: ='Proy. Base'!K58
B20: =B21-1 | E20: ='Proy. Base'!L25 | F20: =(E20-E19)/E19 | I20: ='Proy. Base'!L27 | J20: =(I20/E20) | K20: =E20-I20 | L20: =K20/E20 | M20: ='Proy. Base'!L8 | N20: =(M20-M19)/M19 | O20: ='Proy. Base'!L22 | P20: =(O20-O19)/O19 | Q20: =O20/M20 | R20: =(O20-O19)/O19 | S20: ='Proy. Base'!L24 | T20: ='Proy. Base'!L59 | U20: =(T20-T19)/T19 | V20: ='Proy. Base'!L58
B21: 2035 | E21: ='Proy. Base'!M25 | F21: =(E21-E20)/E20 | I21: ='Proy. Base'!M27 | J21: =(I21/E21) | K21: =E21-I21 | L21: =K21/E21 | M21: ='Proy. Base'!M8 | N21: =(M21-M20)/M20 | O21: ='Proy. Base'!M22 | P21: =(O21-O20)/O20 | Q21: =O21/M21 | R21: =(O21-O20)/O20 | S21: ='Proy. Base'!M24 | T21: ='Proy. Base'!M59 | U21: =(T21-T20)/T20 | V21: ='Proy. Base'!M58
B24: años inversión | C24: rent. Esperada | D24: Precio actual | E24: Nota
B25: 10 | C25: 0.1 | D25: 238 | E25: =Examen!A2/10
B31: Resumen BPA futuro y precio de salida por PER (precio actual en D25) | C31: Años | D31: BPA | E31: PER de salida (Escenarios) | F31: Precio de salida | G31: Rentabilidad anual vs precio actual
B33: Optimista | C33: 5 | D33: ='Proy. Optimista'!H25 | E33: =Escenarios!C$77 | F33: =$D33*E33 | G33: =(F33/$D$25)^(1/$C33)-1
B34: Base | C34: 5 | D34: ='Proy. Base'!H25 | E34: =Escenarios!D$77 | F34: =$D34*E34 | G34: =(F34/$D$25)^(1/$C34)-1
B35: Adverso | C35: 5 | D35: ='Proy. Adverso'!H25 | E35: =Escenarios!E$77 | F35: =$D35*E35 | G35: =(F35/$D$25)^(1/$C35)-1
B37: Optimista | C37: 10 | D37: ='Proy. Optimista'!M25 | E37: =Escenarios!C$77 | F37: =$D37*E37 | G37: =(F37/$D$25)^(1/$C37)-1
B38: Base | C38: 10 | D38: ='Proy. Base'!M25 | E38: =Escenarios!D$77 | F38: =$D38*E38 | G38: =(F38/$D$25)^(1/$C38)-1
B39: Adverso | C39: 10 | D39: ='Proy. Adverso'!M25 | E39: =Escenarios!E$77 | F39: =$D39*E39 | G39: =(F39/$D$25)^(1/$C39)-1
B43: Análisis de riesgo de la inversión en ADBE (método «Parte II · El riesgo»)
B44: Todo enlazado a la hoja Escenarios y a las proyecciones. Azul: datos que puedes cambiar · Verde: enlaces · Amarillo: resultados clave.
B46: 1. Umbral: lo que el precio exige al futuro
B47: Precio pagado P (USD) | C47: =Escenarios!B5 | D47: Precio actual de la acción
B48: Rentabilidad exigida r | C48: =Escenarios!B7 | D48: Coste de oportunidad, sin prima de riesgo (el riesgo va en los escenarios)
B49: Horizonte n (años) | C49: =Escenarios!B8 | D49: Plazo del test de cobertura
B50: PER pagado | C50: =Escenarios!B13 | D50: Precio / BPA del último ejercicio
B51: Margen de seguridad exigido | C51: =Escenarios!B9 | D51: Distancia mínima deseada entre valor estimado y precio
B53: 2. Distribución de valores futuros en el año n
B54: Escenario | C54: Valor futuro (VF) | D54: Probabilidad | E54: Rentabilidad anual | F54: Exceso (+) / déficit (−) vs umbral | G54: Ponderado por probabilidad | H54: % del riesgo asumido | J54: Probabilidad de prueba | K54: Ponderado (prueba) | L54: Nota
...

Sheet Escenarios
A1: ADOBE (ADBE) · Escenarios y análisis de viabilidad
A2: Proyección a 10 años en cuatro escenarios y análisis de viabilidad según «Parte II. El riesgo». Azul: datos que puedes cambiar. Verde: enlaces a otras hojas. Amarillo: resultados clave.
A4: 1. Parámetros del inversor
A5: Precio actual (USD) | B5: ='Modelo EPS'!D25 | C5: Enlazado al precio actual del Modelo EPS.
A6: Fecha del precio | B6: 05-10-2026 | C6: Cierre de Nasdaq.
A7: Rentabilidad exigida r (coste de oportunidad) | B7: 0.1 | C7: Rentabilidad esperada de tu mejor alternativa, sin prima de riesgo: el riesgo va en los escenarios.
A8: Horizonte n (años, de 1 a 10) | B8: 10 | C8: Plazo del test de cobertura.
A9: Margen de seguridad exigido | B9: 0.15 | C9: Distancia mínima entre valor estimado y precio.
A10: Crecimiento a largo plazo (PIB nominal) | B10: 0.04 | C10: Crecimiento de madurez para el escenario base y el PER justificado.
A11: Años para llegar a los márgenes de cada escenario | B11: 5 | C11: Los márgenes pasan en línea recta del último real al del escenario.
A12: BPA diluido del último ejercicio | B12: =PyG!M29 | C12: FY2025.
A13: PER pagado (precio / BPA) | B13: =B5/B12
A15: 2. Histórico y fase de la empresa
A16: Ejercicio | D16: 2016 | E16: 2017 | F16: 2018 | G16: 2019 | H16: 2020 | I16: 2021 | J16: 2022 | K16: 2023 | L16: 2024 | M16: 2025
A17: Ventas (M$) | D17: =PyG!D8 | E17: =PyG!E8 | F17: =PyG!F8 | G17: =PyG!G8 | H17: =PyG!H8 | I17: =PyG!I8 | J17: =PyG!J8 | K17: =PyG!K8 | ... M17: =PyG!M8
A18: Crecimiento de ventas | E18: =E17/D17-1 | F18: =F17/E17-1 | G18: =G17/F17-1 | H18: =H17/G17-1 | I18: =I17/H17-1 | J18: =J17/I17-1 | K18: =K17/J17-1 | L18: =L17/K17-1 | M18: =M17/L17-1
A19: Margen bruto | D19: =PyG!D10/PyG!D8 | E19: =PyG!E10/PyG!E8 | F19: =PyG!F10/PyG!F8 | G19: =PyG!G10/PyG!G8 | H19: =PyG!H10/PyG!H8 | I19: =PyG!I10/PyG!I8 | J19: =PyG!J10/PyG!J8 | K19: =PyG!K10/PyG!K8 | ... M19: =PyG!M10/PyG!M8
A20: Margen operativo | D20: =PyG!D15/PyG!D8 | E20: =PyG!E15/PyG!E8 | F20: =PyG!F15/PyG!F8 | G20: =PyG!G15/PyG!G8 | H20: =PyG!H15/PyG!H8 | I20: =PyG!I15/PyG!I8 | J20: =PyG!J15/PyG!J8 | K20: =PyG!K15/PyG!K8 | ... M20: =PyG!M15/PyG!M8
A21: Margen neto | D21: =PyG!D23/PyG!D8 | E21: =PyG!E23/PyG!E8 | F21: =PyG!F23/PyG!F8 | G21: =PyG!G23/PyG!G8 | H21: =PyG!H23/PyG!H8 | I21: =PyG!I23/PyG!I8 | J21: =PyG!J23/PyG!J8 | K21: =PyG!K23/PyG!K8 | ... M21: =PyG!M23/PyG!M8
A22: ROE (beneficio / patrimonio) | D22: =PyG!D23/Balance!D26 | E22: =PyG!E23/Balance!E26 | F22: =PyG!F23/Balance!F26 | G22: =PyG!G23/Balance!G26 | H22: =PyG!H23/Balance!H26 | I22: =PyG!I23/Balance!I26 | J22: =PyG!J23/Balance!J26 | K22: =PyG!K23/Balance!K26 | ... M22: =PyG!M23/Balance!M26
A23: Acciones diluidas (M) | D23: =PyG!D27 | E23: =PyG!E27 | F23: =PyG!F27 | G23: =PyG!G27 | H23: =PyG!H27 | I23: =PyG!I27 | J23: =PyG!J27 | K23: =PyG!K27 | ... M23: =PyG!M27
A24: BPA diluido | D24: =PyG!D29 | E24: =PyG!E29 | F24: =PyG!F29 | G24: =PyG!G29 | H24: =PyG!H29 | I24: =PyG!I29 | J24: =PyG!J29 | K24: =PyG!K29 | ... M24: =PyG!M29
A25: PER (precio medio del ejercicio / BPA) | D25: ='Modelo EPS'!H2 | E25: ='Modelo EPS'!H3 | F25: ='Modelo EPS'!H4 | G25: ='Modelo EPS'!H5 | H25: ='Modelo EPS'!H6 | I25: ='Modelo EPS'!H7 | J25: ='Modelo EPS'!H8 | K25: ='Modelo EPS'!H9 | L25: ='Modelo EPS'!H10 | M25: ='Modelo EPS'!H11
A27: Crecimiento anual de ventas, últimos 3 años | B27: =(M17/J17)^(1/3)-1 | C27: g3: ritmo reciente.
A28: Crecimiento anual de ventas, últimos 5 años | B28: =(M17/H17)^(1/5)-1
A29: Crecimiento anual de ventas, 2016-2025 | B29: =(M17/D17)^(1/9)-1 | C29: g9: ritmo de largo plazo.
A30: Años con caída de ventas (últimos 9) | B30: =COUNTIF(E18:M18,"<0")
A31: Margen bruto del último año | B31: =M19
A32: Margen bruto medio 5 años | B32: =SUM(PyG!I10:M10)/SUM(PyG!I8:M8)
A33: Margen bruto medio 10 años | B33: =SUM(PyG!D10:M10)/SUM(PyG!D8:M8)
A34: Margen bruto mínimo 10 años | B34: =MIN(D19:M19)
A35: Margen bruto máximo 10 años | B35: =MAX(D19:M19)
A36: Margen operativo del último año | B36: =M20
A37: Margen operativo medio 5 años | B37: =SUM(PyG!I15:M15)/SUM(PyG!I8:M8)
A38: Margen operativo medio 10 años | B38: =SUM(PyG!D15:M15)/SUM(PyG!D8:M8)
A39: Margen operativo mínimo 10 años | B39: =MIN(D20:M20)
A40: Margen operativo máximo 10 años | B40: =MAX(D20:M20)
A41: ROE medio 5 años | B41: =AVERAGE(I22:M22) | C41: Rentabilidad del capital para el PER justificado.
A42: Variación anual de acciones, últimos 5 años | B42: =(M23/H23)^(1/5)-1 | C42: Negativo = recompra neta.
A43: Recompras / flujo de caja libre, 5 años | B43: =MIN(MAX(-SUM('Cash Flow'!I27:M27)/(SUM('Cash Flow'!I15:M15)+SUM('Cash Flow'!I16:M16)),0),1.2) | C43: Parte del flujo de caja libre que se ha destinado a recomprar acciones.
...

Sheet PyG
C7: Annual Data | Millions of US $ except per share data | D7: 2016 | E7: 2017 | F7: 2018 | G7: 2019 | H7: 2020 | I7: 2021 | J7: 2022 | K7: 2023 | L7: 2024 | M7: 2025
C8: Revenue | D8: 5854.43 | E8: 7301.505 | F8: 9030 | G8: 11171 | H8: 12868 | I8: 15785 | J8: 17606 | K8: 19409 | L8: 21505 | M8: 23769
C9: Cost Of Goods Sold | D9: 819.908 | E9: 1010.491 | F9: 1195 | G9: 1673 | H9: 1722 | I9: 1865 | J9: 2165 | K9: 2354 | L9: 2358 | M9: 2551
C10: Gross Profit | D10: 5034.522 | E10: 6291.014 | F10: 7835 | G10: 9498 | H10: 11146 | I10: 13920 | J10: 15441 | K10: 17055 | L10: 19147 | M10: 21218
C11: Research And Development Expenses | D11: 975.987 | E11: 1224.059 | F11: 1538 | G11: 1930 | H11: 2188 | I11: 2540 | J11: 2987 | K11: 3473 | L11: 3944 | M11: 4294
C12: SG&A Expenses | D12: 2486.399 | E12: 2822.298 | F12: 3366 | G12: 4125 | H12: 4559 | I12: 5406 | J12: 6187 | K12: 6764 | L12: 7293 | M12: 8061
C13: Other Operating Income Or Expenses | E13: -1000 | L13: -1000
C14: Operating Expenses | D14: 3540.92 | E14: 4122.919 | F14: 4995 | G14: 6230 | H14: 6909 | I14: 8118 | J14: 9343 | K14: 10405 | L14: 12406 | M14: 12512
C15: Operating Income | D15: 1493.602 | E15: 2168.095 | F15: 2840 | G15: 3268 | H15: 4237 | I15: 5802 | J15: 6098 | K15: 6650 | L15: 6741 | M15: 8706
C16: Total Non-Operating Income/Expense | D16: -58.464 | E16: -30.454 | F16: -46 | G16: -63 | H16: -61 | I16: -97 | J16: -90 | K16: 149 | L16: 190 | M16: 28
C17: Pre-Tax Income | D17: 1435.138 | E17: 2137.641 | F17: 2794 | G17: 3205 | H17: 4176 | I17: 5705 | J17: 6008 | K17: 6799 | L17: 6931 | M17: 8734
C18: Income Taxes | D18: 266.356 | E18: 443.687 | F18: 203 | G18: 254 | H18: -1084 | I18: 883 | J18: 1252 | K18: 1371 | L18: 1371 | M18: 1604
C19: Income After Taxes | D19: 1168.782 | E19: 1693.954 | F19: 2591 | G19: 2951 | H19: 5260 | I19: 4822 | J19: 4756 | K19: 5428 | L19: 5560 | M19: 7130
C20: Other Income
C21: Income From Continuous Operations | D21: 1168.782 | E21: 1693.954 | F21: 2591 | G21: 2951 | H21: 5260 | I21: 4822 | J21: 4756 | K21: 5428 | L21: 5560 | M21: 7130
C22: Income From Discontinued Operations
C23: Net Income | D23: 1168.782 | E23: 1693.954 | F23: 2591 | G23: 2951 | H23: 5260 | I23: 4822 | J23: 4756 | K23: 5428 | L23: 5560 | M23: 7130
C24: EBITDA | D24: 1825.137 | E24: 2494.092 | F24: 3186 | G24: 4025 | H24: 4994 | I24: 6590 | J24: 6954 | K24: 7522 | L24: 7598 | M24: 9524
C25: EBIT | D25: 1493.602 | E25: 2168.095 | F25: 2840 | G25: 3268 | H25: 4237 | I25: 5802 | J25: 6098 | K25: 6650 | L25: 6741 | M25: 8706
C26: Basic Shares Outstanding | D26: 498 | E26: 494 | F26: 491 | G26: 486 | H26: 481 | I26: 477 | J26: 470 | K26: 457 | L26: 447 | M26: 426
C27: Shares Outstanding | D27: 504 | E27: 501 | F27: 498 | G27: 492 | H27: 485 | I27: 481 | J27: 471 | K27: 459 | L27: 450 | M27: 427
C28: Basic EPS | D28: 2.35 | E28: 3.43 | F28: 5.28 | G28: 6.07 | H28: 10.94 | I28: 10.1 | J28: 10.13 | K28: 11.87 | L28: 12.43 | M28: 16.73
C29: EPS - Earnings Per Share | D29: 2.32 | E29: 3.38 | F29: 5.2 | G29: 6 | H29: 10.83 | I29: 10.02 | J29: 10.1 | K29: 11.82 | L29: 12.36 | M29: 16.7

Sheet Balance
C4: Annual Data | Millions of US except per share data | D4: 2016 | E4: 2017 | F4: 2018 | G4: 2019 | H4: 2020 | I4: 2021 | J4: 2022 | K4: 2023 | L4: 2024 | M4: 2025
C5: Cash On Hand | D5: 4761.3 | E5: 5819.774 | F5: 3228.962 | G5: 4177 | H5: 5992 | I5: 5798 | J5: 6096 | K5: 7842 | L5: 7886 | M5: 6595
C6: Receivables | D6: 833.033 | E6: 1217.968 | F6: 1315.578 | G6: 1535 | H6: 1398 | I6: 1878 | J6: 2065 | K6: 2224 | L6: 2072 | M6: 2344
C7: Inventory
C8: Pre-Paid Expenses | D8: 245.441 | E8: 210.071 | F8: 312.499 | G8: 783 | H8: 756 | I8: 993 | J8: 835 | K8: 1018 | L8: 1274 | M8: 1224
C9: Other Current Assets
C10: Total Current Assets | D10: 5839.774 | E10: 7247.813 | F10: 4857.039 | G10: 6495 | H10: 8146 | I10: 8669 | J10: 8996 | K10: 11084 | L10: 11232 | M10: 10163
C11: Property, Plant, And Equipment | D11: 816.264 | E11: 936.976 | F11: 1075.072 | G11: 1293 | H11: 1517 | I11: 1673 | J11: 1908 | K11: 2030 | L11: 1936 | M11: 1873
C12: Long-Term Investments | D12: 80.439 | M12: 80.439
C13: Goodwill And Intangible Assets | D13: 5820.879 | E13: 6207.219 | F13: 12650.05 | G13: 12412 | H13: 12101 | I13: 14488 | J13: 14236 | K13: 13893 | L13: 13570 | M13: 13352
C14: Other Long-Term Assets | D14: 139.89 | E14: 143.548 | F14: 186.522 | G14: 562 | H14: 663 | I14: 883 | J14: 841 | K14: 1223 | L14: 1554 | M14: 1610
C15: Total Long-Term Assets | D15: 6857.472 | E15: 7287.743 | F15: 13911.64 | G15: 14267 | H15: 16138 | I15: 18572 | J15: 18169 | K15: 18695 | L15: 18998 | M15: 19333
C16: Total Assets | D16: 12697.25 | E16: 14535.56 | F16: 18768.68 | G16: 20762 | H16: 24284 | I16: 27241 | J16: 27165 | K16: 29779 | L16: 30230 | M16: 29496
C17: Total Current Liabilities | D17: 2811.635 | E17: 3527.457 | F17: 4301.126 | G17: 8191 | H17: 5512 | I17: 6932 | J17: 8128 | K17: 8251 | L17: 10521 | M17: 10200
C18: Long Term Debt | D18: 1892.2 | E18: 1881.421 | F18: 4124.8 | G18: 989 | H18: 4117 | I18: 4123 | J18: 3629 | K18: 3634 | L18: 4129 | M18: 6210
C19: Other Non-Current Liabilities | D19: 281.785 | E19: 298.276 | F19: 796.31 | G19: 789 | H19: 752 | I19: 791 | J19: 823 | K19: 890 | L19: 994 | M19: 977
C20: Total Long Term Liabilities | D20: 2460.776 | E20: 2548.23 | F20: 5105.442 | G20: 2041 | H20: 5508 | I20: 5512 | J20: 4986 | K20: 5010 | L20: 5604 | M20: 7673
C21: Total Liabilities | D21: 5272.411 | E21: 6075.687 | F21: 9406.568 | G21: 10232 | H21: 11020 | I21: 12444 | J21: 13114 | K21: 13261 | L21: 16125 | M21: 17873
C22: Common Stock Net | D22: 0.061 | E22: 0.061 | F22: 0.061
C23: Retained Earnings (Accumulated Deficit) | D23: 8114.517 | E23: 9573.87 | F23: 11815.6 | G23: 14829 | H23: 19611 | I23: 23905 | J23: 28319 | K23: 33346 | L23: 38470 | M23: 45354
C24: Comprehensive Income | D24: -173.602 | E24: -111.821 | F24: -148.13 | G24: -188 | H24: -158 | I24: -137 | J24: -293 | K24: -285 | L24: -201 | M24: -245
C25: Other Share Holders Equity
C26: Share Holder Equity | D26: 7424.835 | E26: 8459.869 | F26: 9362.114 | G26: 10530 | H26: 13264 | I26: 14797 | J26: 14051 | K26: 16518 | L26: 14105 | M26: 11623
C27: Total Liabilities And Share Holders Equity | D27: 12697.25 | E27: 14535.56 | F27: 18768.68 | G27: 20762 | H27: 24284 | I27: 27241 | J27: 27165 | K27: 29779 | L27: 30230 | M27: 29496

Sheet Cash Flow
C5: Annual Data | Millions of US except per share data | D5: 2016 | E5: 2017 | F5: 2018 | G5: 2019 | H5: 2020 | I5: 2021 | J5: 2022 | K5: 2023 | L5: 2024 | M5: 2025
C6: Net Income/Loss | D6: 1168.782 | E6: 1693.954 | F6: 2591 | G6: 2951 | H6: 5260 | I6: 4822 | J6: 4756 | K6: 5428 | L6: 5560 | M6: 7130
C7: Total Depreciation And Amortization - Cash Flow | D7: 331.535 | E7: 325.997 | F7: 346 | G7: 757 | H7: 757 | I7: 788 | J7: 856 | K7: 872 | L7: 857 | M7: 818
C8: Other Non-Cash Items | D8: 303.581 | E8: 505.208 | F8: 149 | G8: 757 | H8: -476 | I8: 1328 | J8: 1890 | K8: 1357 | L8: 1495 | M8: 1478
C9: Total Non-Cash Items | D9: 635.116 | E9: 831.205 | F9: 495 | G9: 1514 | H9: 281 | I9: 2116 | J9: 2746 | K9: 2229 | L9: 2352 | M9: 2296
C10: Change In Accounts Receivable | D10: -160.416 | E10: -187.173 | F10: -2 | G10: -188 | H10: 106 | I10: -430 | J10: -198 | K10: -159 | L10: 143 | M10: -275
C11: Change In Inventories
C12: Change In Accounts Payable | D12: -6.281 | E12: -45.186 | F12: 55 | G12: 23 | H12: 96 | I12: -20 | J12: 66 | K12: -4 | L12: 44 | M12: 64
C13: Change In Assets/Liabilities | D13: 453.819 | E13: 503.442 | F13: 367 | G13: -54 | H13: -30 | I13: 578 | J13: 442 | K13: -282 | L13: -307 | M13: 681
C14: Total Change In Assets/Liabilities | D14: 395.83 | E14: 387.694 | F14: 943 | G14: -43 | H14: 186 | I14: 292 | J14: 336 | K14: -355 | L14: 144 | M14: 605
C15: Cash Flow From Operating Activities | D15: 2199.728 | E15: 2912.853 | F15: 4029 | G15: 4422 | H15: 5727 | I15: 7230 | J15: 7838 | K15: 7302 | L15: 8056 | M15: 10031
C16: Net Change In Property, Plant, And Equipment | D16: -203.805 | E16: -178.122 | F16: -267 | G16: -395 | H16: -419 | I16: -348 | J16: -442 | K16: -360 | L16: -183 | M16: -179
C17: Net Change In Intangible Assets
C18: Net Acquisitions/Divestitures | D18: -48.427 | E18: -459.626 | F18: -6314 | G18: -101 | I18: -2682 | J18: -126 | M18: -17
C19: Net Change In Short-term Investments | D19: -655.145 | E19: 222.655 | F19: 1909 | G19: 86 | H19: 11 | I19: -465 | J19: 44 | K19: 1188 | L19: 438 | M19: -860
C20: Net Change In Long-Term Investments | D20: -52.656 | E20: -27.784 | F20: -13 | G20: -4 | H20: -6 | I20: -42 | J20: -46 | K20: -53 | L20: -108 | M20: -134
C21: Net Change In Investments - Total | D21: -707.801 | E21: 194.871 | F21: 1896 | G21: 4 | H21: 5 | I21: -507 | J21: -2 | K21: 1135 | L21: 330 | M21: -994
C22: Investing Activities - Other | K22: 1 | L22: 2 | M22: 3
C23: Cash Flow From Investing Activities | D23: -960.033 | E23: -442.877 | F23: -4685 | G23: -456 | H23: -414 | I23: -3537 | J23: -570 | K23: 776 | L23: 149 | M23: -1187
C24: Net Long-Term Debt | D24: -0.108 | F24: 2248 | H24: -6 | K24: -500 | L24: 1997 | M24: 497
C25: Net Current Debt
C26: Debt Issuance/Retirement Net - Total | D26: -0.108 | F26: 2248 | H26: -6 | K26: -500 | L26: 1997 | M26: 497
C27: Net Common Equity Issued/Repurchased | D27: -929.303 | E27: -941.649 | F27: -1859 | G27: -2517 | H27: -2780 | I27: -3659 | J27: -6272 | K27: -4086 | L27: -9139 | M27: -10933
C28: Net Total Equity Issued/Repurchased | D28: -929.303 | E28: -941.649 | F28: -1859 | G28: -2517 | H28: -2780 | I28: -3659 | J28: -6272 | K28: -4086 | L28: -9139 | M28: -10933
C29: Total Common And Preferred Stock Dividends Paid
C30: Financial Activities - Other | D30: -161.295 | E30: -242.086 | F30: -394 | G30: -429 | H30: -702 | I30: -642 | J30: -553 | K30: -596 | L30: -582 | M30: -624
C31: Cash Flow From Financial Activities | D31: -1090.706 | E31: -1183.735 | F31: -5 | G31: -2946 | H31: -3488 | I31: -4301 | J31: -6825 | K31: -5182 | L31: -7724 | M31: -11060
C32: Net Cash Flow | D32: 134.755 | E32: 1294.757 | F32: -663 | G32: 1007 | H32: 1828 | I32: -634 | J32: 392 | K32: 2905 | L32: 472 | M32: -2182
C33: Stock-Based Compensation | D33: 349.297 | E33: 454.472 | F33: 610 | G33: 788 | H33: 909 | I33: 1069 | J33: 1440 | K33: 1718 | L33: 1833 | M33: 1942
C34: Common Stock Dividends Paid

Sheet Proy. Optimista
A1: ADOBE · Proyección del escenario optimista
A2: Millones de USD salvo datos por acción. Supuestos en la hoja «Escenarios». La columna 2025 es real.
A4: Ejercicio | C4: 2025 real | D4: 2026 | E4: 2027 | F4: 2028 | G4: 2029 | H4: 2030 | I4: 2031 | J4: 2032 | K4: 2033 | L4: 2034 | M4: 2035
A5: Año de proyección | C5: 0 | D5: 1 | E5: 2 | F5: 3 | G5: 4 | H5: 5 | I5: 6 | J5: 7 | K5: 8 | L5: 9 | M5: 10
A6: CUENTA DE RESULTADOS
A7: Crecimiento de ventas | C7: =PyG!M8/PyG!L8-1 | D7: =Escenarios!$C$72+(Escenarios!$C$73-Escenarios!$C$72)*(D$5-1)/9 | E7: =Escenarios!$C$72+(Escenarios!$C$73-Escenarios!$C$72)*(E$5-1)/9 | F7: =Escenarios!$C$72+(Escenarios!$C$73-Escenarios!$C$72)*(F$5-1)/9 | G7: =Escenarios!$C$72+(Escenarios!$C$73-Escenarios!$C$72)*(G$5-1)/9 | H7: =Escenarios!$C$72+(Escenarios!$C$73-Escenarios!$C$72)*(H$5-1)/9 | I7: =Escenarios!$C$72+(Escenarios!$C$73-Escenarios!$C$72)*(I$5-1)/9 | J7: =Escenarios!$C$72+(Escenarios!$C$73-Escenarios!$C$72)*(J$5-1)/9 | K7: =Escenarios!$C$72+(Escenarios!$C$73-Escenarios!$C$72)*(K$5-1)/9 | ... M7: =Escenarios!$C$72+(Escenarios!$C$73-Escenarios!$C$72)*(M$5-1)/9
A8: Ventas | C8: =PyG!M8 | D8: =C8*(1+D7) | E8: =D8*(1+E7) | F8: =E8*(1+F7) | G8: =F8*(1+G7) | H8: =G8*(1+H7) | I8: =H8*(1+I7) | J8: =I8*(1+J7) | K8: =J8*(1+K7) | ... M8: =L8*(1+M7)
A9: Coste de ventas | C9: =PyG!M9 | D9: =D8*(1-D11) | E9: =E8*(1-E11) | F9: =F8*(1-F11) | G9: =G8*(1-G11) | H9: =H8*(1-H11) | I9: =I8*(1-I11) | J9: =J8*(1-J11) | K9: =K8*(1-K11) | ... M9: =M8*(1-M11)
A10: Margen bruto | C10: =PyG!M10 | D10: =D8-D9 | E10: =E8-E9 | F10: =F8-F9 | G10: =G8-G9 | H10: =H8-H9 | I10: =I8-I9 | J10: =J8-J9 | K10: =K8-K9 | ... M10: =M8-M9
A11: Margen bruto % | C11: =C10/C8 | D11: =$C$11+(Escenarios!$C$74-$C$11)*MIN(D$5/Escenarios!$B$11,1) | E11: =$C$11+(Escenarios!$C$74-$C$11)*MIN(E$5/Escenarios!$B$11,1) | F11: =$C$11+(Escenarios!$C$74-$C$11)*MIN(F$5/Escenarios!$B$11,1) | G11: =$C$11+(Escenarios!$C$74-$C$11)*MIN(G$5/Escenarios!$B$11,1) | H11: =$C$11+(Escenarios!$C$74-$C$11)*MIN(H$5/Escenarios!$B$11,1) | I11: =$C$11+(Escenarios!$C$74-$C$11)*MIN(I$5/Escenarios!$B$11,1) | J11: =$C$11+(Escenarios!$C$74-$C$11)*MIN(J$5/Escenarios!$B$11,1) | K11: =$C$11+(Escenarios!$C$74-$C$11)*MIN(K$5/Escenarios!$B$11,1) | ... M11: =$C$11+(Escenarios!$C$74-$C$11)*MIN(M$5/Escenarios!$B$11,1)
A12: Gastos operativos | C12: =PyG!M14 | D12: =D10-D15 | E12: =E10-E15 | F12: =F10-F15 | G12: =G10-G15 | H12: =H10-H15 | I12: =I10-I15 | J12: =J10-J15 | K12: =K10-K15 | ... M12: =M10-M15
A13: de los cuales I+D | C13: =PyG!M11 | D13: =D12*Escenarios!$B$50 | E13: =E12*Escenarios!$B$50 | F13: =F12*Escenarios!$B$50 | G13: =G12*Escenarios!$B$50 | H13: =H12*Escenarios!$B$50 | I13: =I12*Escenarios!$B$50 | J13: =J12*Escenarios!$B$50 | K13: =K12*Escenarios!$B$50 | ... M13: =M12*Escenarios!$B$50
A14: de los cuales comerciales, generales y otros | C14: =PyG!M14-PyG!M11 | D14: =D12-D13 | E14: =E12-E13 | F14: =F12-F13 | G14: =G12-G13 | H14: =H12-H13 | I14: =I12-I13 | J14: =J12-J13 | K14: =K12-K13 | ... M14: =M12-M13
A15: Resultado operativo (EBIT) | C15: =PyG!M15 | D15: =D8*D16 | E15: =E8*E16 | F15: =F8*F16 | G15: =G8*G16 | H15: =H8*H16 | I15: =I8*I16 | J15: =J8*J16 | K15: =K8*K16 | ... M15: =M8*M16
A16: Margen operativo % | C16: =C15/C8 | D16: =$C$16+(Escenarios!$C$75-$C$16)*MIN(D$5/Escenarios!$B$11,1) | E16: =$C$16+(Escenarios!$C$75-$C$16)*MIN(E$5/Escenarios!$B$11,1) | F16: =$C$16+(Escenarios!$C$75-$C$16)*MIN(F$5/Escenarios!$B$11,1) | G16: =$C$16+(Escenarios!$C$75-$C$16)*MIN(G$5/Escenarios!$B$11,1) | H16: =$C$16+(Escenarios!$C$75-$C$16)*MIN(H$5/Escenarios!$B$11,1) | I16: =$C$16+(Escenarios!$C$75-$C$16)*MIN(I$5/Escenarios!$B$11,1) | J16: =$C$16+(Escenarios!$C$75-$C$16)*MIN(J$5/Escenarios!$B$11,1) | K16: =$C$16+(Escenarios!$C$75-$C$16)*MIN(K$5/Escenarios!$B$11,1) | ... M16: =$C$16+(Escenarios!$C$75-$C$16)*MIN(M$5/Escenarios!$B$11,1)
A17: Amortizaciones | C17: ='Cash Flow'!M7 | D17: =D8*Escenarios!$B$47 | E17: =E8*Escenarios!$B$47 | F17: =F8*Escenarios!$B$47 | G17: =G8*Escenarios!$B$47 | H17: =H8*Escenarios!$B$47 | I17: =I8*Escenarios!$B$47 | J17: =J8*Escenarios!$B$47 | K17: =K8*Escenarios!$B$47 | ... M17: =M8*Escenarios!$B$47
A18: EBITDA | C18: =C15+C17 | D18: =D15+D17 | E18: =E15+E17 | F18: =F15+F17 | G18: =G15+G17 | H18: =H15+H17 | I18: =I15+I17 | J18: =J15+J17 | ... M18: =M15+M17
A19: Resultado no operativo | C19: =PyG!M16 | D19: =D8*Escenarios!$B$46 | E19: =E8*Escenarios!$B$46 | F19: =F8*Escenarios!$B$46 | G19: =G8*Escenarios!$B$46 | H19: =H8*Escenarios!$B$46 | I19: =I8*Escenarios!$B$46 | J19: =J8*Escenarios!$B$46 | K19: =K8*Escenarios!$B$46 | ... M19: =M8*Escenarios!$B$46
A20: Beneficio antes de impuestos | C20: =PyG!M17 | D20: =D15+D19 | E20: =E15+E19 | F20: =F15+F19 | G20: =G15+G19 | H20: =H15+H19 | I20: =I15+I19 | J20: =J15+J19 | K20: =K15+K19 | ... M20: =M15+M19
A21: Impuestos | C21: =PyG!M18 | D21: =MAX(D20,0)*Escenarios!$B$45 | E21: =MAX(E20,0)*Escenarios!$B$45 | F21: =MAX(F20,0)*Escenarios!$B$45 | G21: =MAX(G20,0)*Escenarios!$B$45 | H21: =MAX(H20,0)*Escenarios!$B$45 | I21: =MAX(I20,0)*Escenarios!$B$45 | J21: =MAX(J20,0)*Escenarios!$B$45 | K21: =MAX(K20,0)*Escenarios!$B$45 | ... M21: =MAX(M20,0)*Escenarios!$B$45
A22: Beneficio neto | C22: =PyG!M23 | D22: =D20-D21 | E22: =E20-E21 | F22: =F20-F21 | G22: =G20-G21 | H22: =H20-H21 | I22: =I20-I21 | J22: =J20-J21 | K22: =K20-K21 | ... M22: =M20-M21
A23: Margen neto % | C23: =C22/C8 | D23: =D22/D8 | E23: =E22/E8 | F23: =F22/F8 | G23: =G22/G8 | H23: =H22/H8 | I23: =I22/I8 | J23: =J22/J8 | ... M23: =M22/M8
A24: Acciones diluidas (M) | C24: =PyG!M27 | D24: =IF(D38>0,C24+(D32+D39)/D38,C24) | E24: =IF(E38>0,D24+(E32+E39)/E38,D24) | F24: =IF(F38>0,E24+(F32+F39)/F38,E24) | G24: =IF(G38>0,F24+(G32+G39)/G38,F24) | H24: =IF(H38>0,G24+(H32+H39)/H38,G24) | I24: =IF(I38>0,H24+(I32+I39)/I38,H24) | J24: =IF(J38>0,I24+(J32+J39)/J38,I24) | K24: =IF(K38>0,J24+(K32+K39)/K38,J24) | ... M24: =IF(M38>0,L24+(M32+M39)/M38,L24)
A25: BPA diluido | C25: =PyG!M29 | D25: =D22/D24 | E25: =E22/E24 | F25: =F22/F24 | G25: =G22/G24 | H25: =H22/H24 | I25: =I22/I24 | J25: =J22/J24 | K25: =K22/K24 | ... M25: =M22/M24
A26: Crecimiento del BPA | D26: =IF(C25>0,D25/C25-1,0) | E26: =IF(D25>0,E25/D25-1,0) | F26: =IF(E25>0,F25/E25-1,0) | G26: =IF(F25>0,G25/F25-1,0) | H26: =IF(G25>0,H25/G25-1,0) | I26: =IF(H25>0,I25/H25-1,0) | J26: =IF(I25>0,J25/I25-1,0) | K26: =IF(J25>0,K25/J25-1,0) | ... M26: =IF(L25>0,M25/L25-1,0)
A27: Dividendo por acción | C27: =ABS('Cash Flow'!M29)/C24 | D27: =MAX(D25,0)*Escenarios!$B$44 | E27: =MAX(E25,0)*Escenarios!$B$44 | F27: =MAX(F25,0)*Escenarios!$B$44 | G27: =MAX(G25,0)*Escenarios!$B$44 | H27: =MAX(H25,0)*Escenarios!$B$44 | I27: =MAX(I25,0)*Escenarios!$B$44 | J27: =MAX(J25,0)*Escenarios!$B$44 | K27: =MAX(K25,0)*Escenarios!$B$44 | ... M27: =MAX(M25,0)*Escenarios!$B$44
A29: FLUJO DE CAJA
A30: Beneficio neto | C30: =C22 | D30: =D22 | E30: =E22 | F30: =F22 | G30: =G22 | H30: =H22 | I30: =I22 | J30: =J22 | ... M30: =M22
A31: Amortizaciones | C31: =C17 | D31: =D17 | E31: =E17 | F31: =F17 | G31: =G17 | H31: =H17 | I31: =I17 | J31: =J17 | ... M31: =M17
A32: Remuneración en acciones | C32: ='Cash Flow'!M33 | D32: =D8*Escenarios!$B$49 | E32: =E8*Escenarios!$B$49 | F32: =F8*Escenarios!$B$49 | G32: =G8*Escenarios!$B$49 | H32: =H8*Escenarios!$B$49 | I32: =I8*Escenarios!$B$49 | J32: =J8*Escenarios!$B$49 | K32: =K8*Escenarios!$B$49 | ... M32: =M8*Escenarios!$B$49
A33: Variación del circulante | D33: =-(D46-C46)+(D50-C50) | E33: =-(E46-D46)+(E50-D50) | F33: =-(F46-E46)+(F50-E50) | G33: =-(G46-F46)+(G50-F50) | H33: =-(H46-G46)+(H50-G50) | I33: =-(I46-H46)+(I50-H50) | J33: =-(J46-I46)+(J50-I50) | K33: =-(K46-J46)+(K50-J50) | ... M33: =-(M46-L46)+(M50-L50)
A34: Flujo de caja operativo | C34: ='Cash Flow'!M15 | D34: =SUM(D30:D33) | E34: =SUM(E30:E33) | F34: =SUM(F30:F33) | G34: =SUM(G30:G33) | H34: =SUM(H30:H33) | I34: =SUM(I30:I33) | J34: =SUM(J30:J33) | K34: =SUM(K30:K33) | ... M34: =SUM(M30:M33)
A35: Capex | C35: ='Cash Flow'!M16 | D35: =-D8*Escenarios!$B$48 | E35: =-E8*Escenarios!$B$48 | F35: =-F8*Escenarios!$B$48 | G35: =-G8*Escenarios!$B$48 | H35: =-H8*Escenarios!$B$48 | I35: =-I8*Escenarios!$B$48 | J35: =-J8*Escenarios!$B$48 | K35: =-K8*Escenarios!$B$48 | ... M35: =-M8*Escenarios!$B$48
A36: Flujo de caja libre | C36: =C34+C35 | D36: =D34+D35 | E36: =E34+E35 | F36: =F34+F35 | G36: =G34+G35 | H36: =H34+H35 | I36: =I34+I35 | J36: =J34+J35 | ... M36: =M34+M35
A37: PER supuesto para las recompras | D37: =Escenarios!$B$13+(Escenarios!$C$77-Escenarios!$B$13)*(D$5-1)/9 | E37: =Escenarios!$B$13+(Escenarios!$C$77-Escenarios!$B$13)*(E$5-1)/9 | F37: =Escenarios!$B$13+(Escenarios!$C$77-Escenarios!$B$13)*(F$5-1)/9 | G37: =Escenarios!$B$13+(Escenarios!$C$77-Escenarios!$B$13)*(G$5-1)/9 | H37: =Escenarios!$B$13+(Escenarios!$C$77-Escenarios!$B$13)*(H$5-1)/9 | I37: =Escenarios!$B$13+(Escenarios!$C$77-Escenarios!$B$13)*(I$5-1)/9 | J37: =Escenarios!$B$13+(Escenarios!$C$77-Escenarios!$B$13)*(J$5-1)/9 | K37: =Escenarios!$B$13+(Escenarios!$C$77-Escenarios!$B$13)*(K$5-1)/9 | ... M37: =Escenarios!$B$13+(Escenarios!$C$77-Escenarios!$B$13)*(M$5-1)/9
A38: Precio supuesto para las recompras | D38: =MAX(C25,0)*D37 | E38: =MAX(D25,0)*E37 | F38: =MAX(E25,0)*F37 | G38: =MAX(F25,0)*G37 | H38: =MAX(G25,0)*H37 | I38: =MAX(H25,0)*I37 | J38: =MAX(I25,0)*J37 | K38: =MAX(J25,0)*K37 | ... M38: =MAX(L25,0)*M37
A39: Recompra de acciones | C39: ='Cash Flow'!M27 | D39: =-Escenarios!$C$76*MAX(D36-D22*Escenarios!$B$44,0) | E39: =-Escenarios!$C$76*MAX(E36-E22*Escenarios!$B$44,0) | F39: =-Escenarios!$C$76*MAX(F36-F22*Escenarios!$B$44,0) | G39: =-Escenarios!$C$76*MAX(G36-G22*Escenarios!$B$44,0) | H39: =-Escenarios!$C$76*MAX(H36-H22*Escenarios!$B$44,0) | I39: =-Escenarios!$C$76*MAX(I36-I22*Escenarios!$B$44,0) | J39: =-Escenarios!$C$76*MAX(J36-J22*Escenarios!$B$44,0) | K39: =-Escenarios!$C$76*MAX(K36-K22*Escenarios!$B$44,0) | ... M39: =-Escenarios!$C$76*MAX(M36-M22*Escenarios!$B$44,0)
A40: Dividendos pagados | C40: =-ABS('Cash Flow'!M29) | D40: =-D22*Escenarios!$B$44*(D22>0) | E40: =-E22*Escenarios!$B$44*(E22>0) | F40: =-F22*Escenarios!$B$44*(F22>0) | G40: =-G22*Escenarios!$B$44*(G22>0) | H40: =-H22*Escenarios!$B$44*(H22>0) | I40: =-I22*Escenarios!$B$44*(I22>0) | J40: =-J22*Escenarios!$B$44*(J22>0) | K40: =-K22*Escenarios!$B$44*(K22>0) | ... M40: =-M22*Escenarios!$B$44*(M22>0)
A41: Variación de deuda | D41: =0 | E41: =0 | F41: =0 | G41: =0 | H41: =0 | I41: =0 | J41: =0 | K41: =0 | ... M41: =0
A42: Variación de caja | D42: =D36+D39+D40+D41 | E42: =E36+E39+E40+E41 | F42: =F36+F39+F40+F41 | G42: =G36+G39+G40+G41 | H42: =H36+H39+H40+H41 | I42: =I36+I39+I40+I41 | J42: =J36+J39+J40+J41 | K42: =K36+K39+K40+K41 | ... M42: =M36+M39+M40+M41
...

Sheet Proy. Base
A1: ADOBE · Proyección del escenario base
A2: Millones de USD salvo datos por acción. Supuestos en la hoja «Escenarios». La columna 2025 es real.
A4: Ejercicio | C4: 2025 real | D4: 2026 | E4: 2027 | F4: 2028 | G4: 2029 | H4: 2030 | I4: 2031 | J4: 2032 | K4: 2033 | L4: 2034 | M4: 2035
A5: Año de proyección | C5: 0 | D5: 1 | E5: 2 | F5: 3 | G5: 4 | H5: 5 | I5: 6 | J5: 7 | K5: 8 | L5: 9 | M5: 10
A6: CUENTA DE RESULTADOS
A7: Crecimiento de ventas | C7: =PyG!M8/PyG!L8-1 | D7: =Escenarios!$D$72+(Escenarios!$D$73-Escenarios!$D$72)*(D$5-1)/9 | E7: =Escenarios!$D$72+(Escenarios!$D$73-Escenarios!$D$72)*(E$5-1)/9 | F7: =Escenarios!$D$72+(Escenarios!$D$73-Escenarios!$D$72)*(F$5-1)/9 | G7: =Escenarios!$D$72+(Escenarios!$D$73-Escenarios!$D$72)*(G$5-1)/9 | H7: =Escenarios!$D$72+(Escenarios!$D$73-Escenarios!$D$72)*(H$5-1)/9 | I7: =Escenarios!$D$72+(Escenarios!$D$73-Escenarios!$D$72)*(I$5-1)/9 | J7: =Escenarios!$D$72+(Escenarios!$D$73-Escenarios!$D$72)*(J$5-1)/9 | K7: =Escenarios!$D$72+(Escenarios!$D$73-Escenarios!$D$72)*(K$5-1)/9 | ... M7: =Escenarios!$D$72+(Escenarios!$D$73-Escenarios!$D$72)*(M$5-1)/9
A8: Ventas | C8: =PyG!M8 | D8: =C8*(1+D7) | E8: =D8*(1+E7) | F8: =E8*(1+F7) | G8: =F8*(1+G7) | H8: =G8*(1+H7) | I8: =H8*(1+I7) | J8: =I8*(1+J7) | K8: =J8*(1+K7) | ... M8: =L8*(1+M7)
A9: Coste de ventas | C9: =PyG!M9 | D9: =D8*(1-D11) | E9: =E8*(1-E11) | F9: =F8*(1-F11) | G9: =G8*(1-G11) | H9: =H8*(1-H11) | I9: =I8*(1-I11) | J9: =J8*(1-J11) | K9: =K8*(1-K11) | ... M9: =M8*(1-M11)
A10: Margen bruto | C10: =PyG!M10 | D10: =D8-D9 | E10: =E8-E9 | F10: =F8-F9 | G10: =G8-G9 | H10: =H8-H9 | I10: =I8-I9 | J10: =J8-J9 | K10: =K8-K9 | ... M10: =M8-M9
A11: Margen bruto % | C11: =C10/C8 | D11: =$C$11+(Escenarios!$D$74-$C$11)*MIN(D$5/Escenarios!$B$11,1) | E11: =$C$11+(Escenarios!$D$74-$C$11)*MIN(E$5/Escenarios!$B$11,1) | F11: =$C$11+(Escenarios!$D$74-$C$11)*MIN(F$5/Escenarios!$B$11,1) | G11: =$C$11+(Escenarios!$D$74-$C$11)*MIN(G$5/Escenarios!$B$11,1) | H11: =$C$11+(Escenarios!$D$74-$C$11)*MIN(H$5/Escenarios!$B$11,1) | I11: =$C$11+(Escenarios!$D$74-$C$11)*MIN(I$5/Escenarios!$B$11,1) | J11: =$C$11+(Escenarios!$D$74-$C$11)*MIN(J$5/Escenarios!$B$11,1) | K11: =$C$11+(Escenarios!$D$74-$C$11)*MIN(K$5/Escenarios!$B$11,1) | ... M11: =$C$11+(Escenarios!$D$74-$C$11)*MIN(M$5/Escenarios!$B$11,1)
A12: Gastos operativos | C12: =PyG!M14 | D12: =D10-D15 | E12: =E10-E15 | F12: =F10-F15 | G12: =G10-G15 | H12: =H10-H15 | I12: =I10-I15 | J12: =J10-J15 | K12: =K10-K15 | ... M12: =M10-M15
A13: de los cuales I+D | C13: =PyG!M11 | D13: =D12*Escenarios!$B$50 | E13: =E12*Escenarios!$B$50 | F13: =F12*Escenarios!$B$50 | G13: =G12*Escenarios!$B$50 | H13: =H12*Escenarios!$B$50 | I13: =I12*Escenarios!$B$50 | J13: =J12*Escenarios!$B$50 | K13: =K12*Escenarios!$B$50 | ... M13: =M12*Escenarios!$B$50
A14: de los cuales comerciales, generales y otros | C14: =PyG!M14-PyG!M11 | D14: =D12-D13 | E14: =E12-E13 | F14: =F12-F13 | G14: =G12-G13 | H14: =H12-H13 | I14: =I12-I13 | J14: =J12-J13 | K14: =K12-K13 | ... M14: =M12-M13
A15: Resultado operativo (EBIT) | C15: =PyG!M15 | D15: =D8*D16 | E15: =E8*E16 | F15: =F8*F16 | G15: =G8*G16 | H15: =H8*H16 | I15: =I8*I16 | J15: =J8*J16 | K15: =K8*K16 | ... M15: =M8*M16
A16: Margen operativo % | C16: =C15/C8 | D16: =$C$16+(Escenarios!$D$75-$C$16)*MIN(D$5/Escenarios!$B$11,1) | E16: =$C$16+(Escenarios!$D$75-$C$16)*MIN(E$5/Escenarios!$B$11,1) | F16: =$C$16+(Escenarios!$D$75-$C$16)*MIN(F$5/Escenarios!$B$11,1) | G16: =$C$16+(Escenarios!$D$75-$C$16)*MIN(G$5/Escenarios!$B$11,1) | H16: =$C$16+(Escenarios!$D$75-$C$16)*MIN(H$5/Escenarios!$B$11,1) | I16: =$C$16+(Escenarios!$D$75-$C$16)*MIN(I$5/Escenarios!$B$11,1) | J16: =$C$16+(Escenarios!$D$75-$C$16)*MIN(J$5/Escenarios!$B$11,1) | K16: =$C$16+(Escenarios!$D$75-$C$16)*MIN(K$5/Escenarios!$B$11,1) | ... M16: =$C$16+(Escenarios!$D$75-$C$16)*MIN(M$5/Escenarios!$B$11,1)
A17: Amortizaciones | C17: ='Cash Flow'!M7 | D17: =D8*Escenarios!$B$47 | E17: =E8*Escenarios!$B$47 | F17: =F8*Escenarios!$B$47 | G17: =G8*Escenarios!$B$47 | H17: =H8*Escenarios!$B$47 | I17: =I8*Escenarios!$B$47 | J17: =J8*Escenarios!$B$47 | K17: =K8*Escenarios!$B$47 | ... M17: =M8*Escenarios!$B$47
A18: EBITDA | C18: =C15+C17 | D18: =D15+D17 | E18: =E15+E17 | F18: =F15+F17 | G18: =G15+G17 | H18: =H15+H17 | I18: =I15+I17 | J18: =J15+J17 | ... M18: =M15+M17
A19: Resultado no operativo | C19: =PyG!M16 | D19: =D8*Escenarios!$B$46 | E19: =E8*Escenarios!$B$46 | F19: =F8*Escenarios!$B$46 | G19: =G8*Escenarios!$B$46 | H19: =H8*Escenarios!$B$46 | I19: =I8*Escenarios!$B$46 | J19: =J8*Escenarios!$B$46 | K19: =K8*Escenarios!$B$46 | ... M19: =M8*Escenarios!$B$46
A20: Beneficio antes de impuestos | C20: =PyG!M17 | D20: =D15+D19 | E20: =E15+E19 | F20: =F15+F19 | G20: =G15+G19 | H20: =H15+H19 | I20: =I15+I19 | J20: =J15+J19 | K20: =K15+K19 | ... M20: =M15+M19
A21: Impuestos | C21: =PyG!M18 | D21: =MAX(D20,0)*Escenarios!$B$45 | E21: =MAX(E20,0)*Escenarios!$B$45 | F21: =MAX(F20,0)*Escenarios!$B$45 | G21: =MAX(G20,0)*Escenarios!$B$45 | H21: =MAX(H20,0)*Escenarios!$B$45 | I21: =MAX(I20,0)*Escenarios!$B$45 | J21: =MAX(J20,0)*Escenarios!$B$45 | K21: =MAX(K20,0)*Escenarios!$B$45 | ... M21: =MAX(M20,0)*Escenarios!$B$45
A22: Beneficio neto | C22: =PyG!M23 | D22: =D20-D21 | E22: =E20-E21 | F22: =F20-F21 | G22: =G20-G21 | H22: =H20-H21 | I22: =I20-I21 | J22: =J20-J21 | K22: =K20-K21 | ... M22: =M20-M21
A23: Margen neto % | C23: =C22/C8 | D23: =D22/D8 | E23: =E22/E8 | F23: =F22/F8 | G23: =G22/G8 | H23: =H22/H8 | I23: =I22/I8 | J23: =J22/J8 | ... M23: =M22/M8
A24: Acciones diluidas (M) | C24: =PyG!M27 | D24: =IF(D38>0,C24+(D32+D39)/D38,C24) | E24: =IF(E38>0,D24+(E32+E39)/E38,D24) | F24: =IF(F38>0,E24+(F32+F39)/F38,E24) | G24: =IF(G38>0,F24+(G32+G39)/G38,F24) | H24: =IF(H38>0,G24+(H32+H39)/H38,G24) | I24: =IF(I38>0,H24+(I32+I39)/I38,H24) | J24: =IF(J38>0,I24+(J32+J39)/J38,I24) | K24: =IF(K38>0,J24+(K32+K39)/K38,J24) | ... M24: =IF(M38>0,L24+(M32+M39)/M38,L24)
A25: BPA diluido | C25: =PyG!M29 | D25: =D22/D24 | E25: =E22/E24 | F25: =F22/F24 | G25: =G22/G24 | H25: =H22/H24 | I25: =I22/I24 | J25: =J22/J24 | K25: =K22/K24 | ... M25: =M22/M24
A26: Crecimiento del BPA | D26: =IF(C25>0,D25/C25-1,0) | E26: =IF(D25>0,E25/D25-1,0) | F26: =IF(E25>0,F25/E25-1,0) | G26: =IF(F25>0,G25/F25-1,0) | H26: =IF(G25>0,H25/G25-1,0) | I26: =IF(H25>0,I25/H25-1,0) | J26: =IF(I25>0,J25/I25-1,0) | K26: =IF(J25>0,K25/J25-1,0) | ... M26: =IF(L25>0,M25/L25-1,0)
A27: Dividendo por acción | C27: =ABS('Cash Flow'!M29)/C24 | D27: =MAX(D25,0)*Escenarios!$B$44 | E27: =MAX(E25,0)*Escenarios!$B$44 | F27: =MAX(F25,0)*Escenarios!$B$44 | G27: =MAX(G25,0)*Escenarios!$B$44 | H27: =MAX(H25,0)*Escenarios!$B$44 | I27: =MAX(I25,0)*Escenarios!$B$44 | J27: =MAX(J25,0)*Escenarios!$B$44 | K27: =MAX(K25,0)*Escenarios!$B$44 | ... M27: =MAX(M25,0)*Escenarios!$B$44
A29: FLUJO DE CAJA
A30: Beneficio neto | C30: =C22 | D30: =D22 | E30: =E22 | F30: =F22 | G30: =G22 | H30: =H22 | I30: =I22 | J30: =J22 | ... M30: =M22
A31: Amortizaciones | C31: =C17 | D31: =D17 | E31: =E17 | F31: =F17 | G31: =G17 | H31: =H17 | I31: =I17 | J31: =J17 | ... M31: =M17
A32: Remuneración en acciones | C32: ='Cash Flow'!M33 | D32: =D8*Escenarios!$B$49 | E32: =E8*Escenarios!$B$49 | F32: =F8*Escenarios!$B$49 | G32: =G8*Escenarios!$B$49 | H32: =H8*Escenarios!$B$49 | I32: =I8*Escenarios!$B$49 | J32: =J8*Escenarios!$B$49 | K32: =K8*Escenarios!$B$49 | ... M32: =M8*Escenarios!$B$49
A33: Variación del circulante | D33: =-(D46-C46)+(D50-C50) | E33: =-(E46-D46)+(E50-D50) | F33: =-(F46-E46)+(F50-E50) | G33: =-(G46-F46)+(G50-F50) | H33: =-(H46-G46)+(H50-G50) | I33: =-(I46-H46)+(I50-H50) | J33: =-(J46-I46)+(J50-I50) | K33: =-(K46-J46)+(K50-J50) | ... M33: =-(M46-L46)+(M50-L50)
A34: Flujo de caja operativo | C34: ='Cash Flow'!M15 | D34: =SUM(D30:D33) | E34: =SUM(E30:E33) | F34: =SUM(F30:F33) | G34: =SUM(G30:G33) | H34: =SUM(H30:H33) | I34: =SUM(I30:I33) | J34: =SUM(J30:J33) | K34: =SUM(K30:K33) | ... M34: =SUM(M30:M33)
A35: Capex | C35: ='Cash Flow'!M16 | D35: =-D8*Escenarios!$B$48 | E35: =-E8*Escenarios!$B$48 | F35: =-F8*Escenarios!$B$48 | G35: =-G8*Escenarios!$B$48 | H35: =-H8*Escenarios!$B$48 | I35: =-I8*Escenarios!$B$48 | J35: =-J8*Escenarios!$B$48 | K35: =-K8*Escenarios!$B$48 | ... M35: =-M8*Escenarios!$B$48
A36: Flujo de caja libre | C36: =C34+C35 | D36: =D34+D35 | E36: =E34+E35 | F36: =F34+F35 | G36: =G34+G35 | H36: =H34+H35 | I36: =I34+I35 | J36: =J34+J35 | ... M36: =M34+M35
A37: PER supuesto para las recompras | D37: =Escenarios!$B$13+(Escenarios!$D$77-Escenarios!$B$13)*(D$5-1)/9 | E37: =Escenarios!$B$13+(Escenarios!$D$77-Escenarios!$B$13)*(E$5-1)/9 | F37: =Escenarios!$B$13+(Escenarios!$D$77-Escenarios!$B$13)*(F$5-1)/9 | G37: =Escenarios!$B$13+(Escenarios!$D$77-Escenarios!$B$13)*(G$5-1)/9 | H37: =Escenarios!$B$13+(Escenarios!$D$77-Escenarios!$B$13)*(H$5-1)/9 | I37: =Escenarios!$B$13+(Escenarios!$D$77-Escenarios!$B$13)*(I$5-1)/9 | J37: =Escenarios!$B$13+(Escenarios!$D$77-Escenarios!$B$13)*(J$5-1)/9 | K37: =Escenarios!$B$13+(Escenarios!$D$77-Escenarios!$B$13)*(K$5-1)/9 | ... M37: =Escenarios!$B$13+(Escenarios!$D$77-Escenarios!$B$13)*(M$5-1)/9
A38: Precio supuesto para las recompras | D38: =MAX(C25,0)*D37 | E38: =MAX(D25,0)*E37 | F38: =MAX(E25,0)*F37 | G38: =MAX(F25,0)*G37 | H38: =MAX(G25,0)*H37 | I38: =MAX(H25,0)*I37 | J38: =MAX(I25,0)*J37 | K38: =MAX(J25,0)*K37 | ... M38: =MAX(L25,0)*M37
A39: Recompra de acciones | C39: ='Cash Flow'!M27 | D39: =-Escenarios!$D$76*MAX(D36-D22*Escenarios!$B$44,0) | E39: =-Escenarios!$D$76*MAX(E36-E22*Escenarios!$B$44,0) | F39: =-Escenarios!$D$76*MAX(F36-F22*Escenarios!$B$44,0) | G39: =-Escenarios!$D$76*MAX(G36-G22*Escenarios!$B$44,0) | H39: =-Escenarios!$D$76*MAX(H36-H22*Escenarios!$B$44,0) | I39: =-Escenarios!$D$76*MAX(I36-I22*Escenarios!$B$44,0) | J39: =-Escenarios!$D$76*MAX(J36-J22*Escenarios!$B$44,0) | K39: =-Escenarios!$D$76*MAX(K36-K22*Escenarios!$B$44,0) | ... M39: =-Escenarios!$D$76*MAX(M36-M22*Escenarios!$B$44,0)
A40: Dividendos pagados | C40: =-ABS('Cash Flow'!M29) | D40: =-D22*Escenarios!$B$44*(D22>0) | E40: =-E22*Escenarios!$B$44*(E22>0) | F40: =-F22*Escenarios!$B$44*(F22>0) | G40: =-G22*Escenarios!$B$44*(G22>0) | H40: =-H22*Escenarios!$B$44*(H22>0) | I40: =-I22*Escenarios!$B$44*(I22>0) | J40: =-J22*Escenarios!$B$44*(J22>0) | K40: =-K22*Escenarios!$B$44*(K22>0) | ... M40: =-M22*Escenarios!$B$44*(M22>0)
A41: Variación de deuda | D41: =0 | E41: =0 | F41: =0 | G41: =0 | H41: =0 | I41: =0 | J41: =0 | K41: =0 | ... M41: =0
A42: Variación de caja | D42: =D36+D39+D40+D41 | E42: =E36+E39+E40+E41 | F42: =F36+F39+F40+F41 | G42: =G36+G39+G40+G41 | H42: =H36+H39+H40+H41 | I42: =I36+I39+I40+I41 | J42: =J36+J39+J40+J41 | K42: =K36+K39+K40+K41 | ... M42: =M36+M39+M40+M41
...

Sheet Proy. Adverso
A1: ADOBE · Proyección del escenario adverso
A2: Millones de USD salvo datos por acción. Supuestos en la hoja «Escenarios». La columna 2025 es real.
A4: Ejercicio | C4: 2025 real | D4: 2026 | E4: 2027 | F4: 2028 | G4: 2029 | H4: 2030 | I4: 2031 | J4: 2032 | K4: 2033 | L4: 2034 | M4: 2035
A5: Año de proyección | C5: 0 | D5: 1 | E5: 2 | F5: 3 | G5: 4 | H5: 5 | I5: 6 | J5: 7 | K5: 8 | L5: 9 | M5: 10
A6: CUENTA DE RESULTADOS
A7: Crecimiento de ventas | C7: =PyG!M8/PyG!L8-1 | D7: =Escenarios!$E$72+(Escenarios!$E$73-Escenarios!$E$72)*(D$5-1)/9 | E7: =Escenarios!$E$72+(Escenarios!$E$73-Escenarios!$E$72)*(E$5-1)/9 | F7: =Escenarios!$E$72+(Escenarios!$E$73-Escenarios!$E$72)*(F$5-1)/9 | G7: =Escenarios!$E$72+(Escenarios!$E$73-Escenarios!$E$72)*(G$5-1)/9 | H7: =Escenarios!$E$72+(Escenarios!$E$73-Escenarios!$E$72)*(H$5-1)/9 | I7: =Escenarios!$E$72+(Escenarios!$E$73-Escenarios!$E$72)*(I$5-1)/9 | J7: =Escenarios!$E$72+(Escenarios!$E$73-Escenarios!$E$72)*(J$5-1)/9 | K7: =Escenarios!$E$72+(Escenarios!$E$73-Escenarios!$E$72)*(K$5-1)/9 | ... M7: =Escenarios!$E$72+(Escenarios!$E$73-Escenarios!$E$72)*(M$5-1)/9
A8: Ventas | C8: =PyG!M8 | D8: =C8*(1+D7) | E8: =D8*(1+E7) | F8: =E8*(1+F7) | G8: =F8*(1+G7) | H8: =G8*(1+H7) | I8: =H8*(1+I7) | J8: =I8*(1+J7) | K8: =J8*(1+K7) | ... M8: =L8*(1+M7)
A9: Coste de ventas | C9: =PyG!M9 | D9: =D8*(1-D11) | E9: =E8*(1-E11) | F9: =F8*(1-F11) | G9: =G8*(1-G11) | H9: =H8*(1-H11) | I9: =I8*(1-I11) | J9: =J8*(1-J11) | K9: =K8*(1-K11) | ... M9: =M8*(1-M11)
A10: Margen bruto | C10: =PyG!M10 | D10: =D8-D9 | E10: =E8-E9 | F10: =F8-F9 | G10: =G8-G9 | H10: =H8-H9 | I10: =I8-I9 | J10: =J8-J9 | K10: =K8-K9 | ... M10: =M8-M9
A11: Margen bruto % | C11: =C10/C8 | D11: =$C$11+(Escenarios!$E$74-$C$11)*MIN(D$5/Escenarios!$B$11,1) | E11: =$C$11+(Escenarios!$E$74-$C$11)*MIN(E$5/Escenarios!$B$11,1) | F11: =$C$11+(Escenarios!$E$74-$C$11)*MIN(F$5/Escenarios!$B$11,1) | G11: =$C$11+(Escenarios!$E$74-$C$11)*MIN(G$5/Escenarios!$B$11,1) | H11: =$C$11+(Escenarios!$E$74-$C$11)*MIN(H$5/Escenarios!$B$11,1) | I11: =$C$11+(Escenarios!$E$74-$C$11)*MIN(I$5/Escenarios!$B$11,1) | J11: =$C$11+(Escenarios!$E$74-$C$11)*MIN(J$5/Escenarios!$B$11,1) | K11: =$C$11+(Escenarios!$E$74-$C$11)*MIN(K$5/Escenarios!$B$11,1) | ... M11: =$C$11+(Escenarios!$E$74-$C$11)*MIN(M$5/Escenarios!$B$11,1)
A12: Gastos operativos | C12: =PyG!M14 | D12: =D10-D15 | E12: =E10-E15 | F12: =F10-F15 | G12: =G10-G15 | H12: =H10-H15 | I12: =I10-I15 | J12: =J10-J15 | K12: =K10-K15 | ... M12: =M10-M15
A13: de los cuales I+D | C13: =PyG!M11 | D13: =D12*Escenarios!$B$50 | E13: =E12*Escenarios!$B$50 | F13: =F12*Escenarios!$B$50 | G13: =G12*Escenarios!$B$50 | H13: =H12*Escenarios!$B$50 | I13: =I12*Escenarios!$B$50 | J13: =J12*Escenarios!$B$50 | K13: =K12*Escenarios!$B$50 | ... M13: =M12*Escenarios!$B$50
A14: de los cuales comerciales, generales y otros | C14: =PyG!M14-PyG!M11 | D14: =D12-D13 | E14: =E12-E13 | F14: =F12-F13 | G14: =G12-G13 | H14: =H12-H13 | I14: =I12-I13 | J14: =J12-J13 | K14: =K12-K13 | ... M14: =M12-M13
A15: Resultado operativo (EBIT) | C15: =PyG!M15 | D15: =D8*D16 | E15: =E8*E16 | F15: =F8*F16 | G15: =G8*G16 | H15: =H8*H16 | I15: =I8*I16 | J15: =J8*J16 | K15: =K8*K16 | ... M15: =M8*M16
A16: Margen operativo % | C16: =C15/C8 | D16: =$C$16+(Escenarios!$E$75-$C$16)*MIN(D$5/Escenarios!$B$11,1) | E16: =$C$16+(Escenarios!$E$75-$C$16)*MIN(E$5/Escenarios!$B$11,1) | F16: =$C$16+(Escenarios!$E$75-$C$16)*MIN(F$5/Escenarios!$B$11,1) | G16: =$C$16+(Escenarios!$E$75-$C$16)*MIN(G$5/Escenarios!$B$11,1) | H16: =$C$16+(Escenarios!$E$75-$C$16)*MIN(H$5/Escenarios!$B$11,1) | I16: =$C$16+(Escenarios!$E$75-$C$16)*MIN(I$5/Escenarios!$B$11,1) | J16: =$C$16+(Escenarios!$E$75-$C$16)*MIN(J$5/Escenarios!$B$11,1) | K16: =$C$16+(Escenarios!$E$75-$C$16)*MIN(K$5/Escenarios!$B$11,1) | ... M16: =$C$16+(Escenarios!$E$75-$C$16)*MIN(M$5/Escenarios!$B$11,1)
A17: Amortizaciones | C17: ='Cash Flow'!M7 | D17: =D8*Escenarios!$B$47 | E17: =E8*Escenarios!$B$47 | F17: =F8*Escenarios!$B$47 | G17: =G8*Escenarios!$B$47 | H17: =H8*Escenarios!$B$47 | I17: =I8*Escenarios!$B$47 | J17: =J8*Escenarios!$B$47 | K17: =K8*Escenarios!$B$47 | ... M17: =M8*Escenarios!$B$47
A18: EBITDA | C18: =C15+C17 | D18: =D15+D17 | E18: =E15+E17 | F18: =F15+F17 | G18: =G15+G17 | H18: =H15+H17 | I18: =I15+I17 | J18: =J15+J17 | ... M18: =M15+M17
A19: Resultado no operativo | C19: =PyG!M16 | D19: =D8*Escenarios!$B$46 | E19: =E8*Escenarios!$B$46 | F19: =F8*Escenarios!$B$46 | G19: =G8*Escenarios!$B$46 | H19: =H8*Escenarios!$B$46 | I19: =I8*Escenarios!$B$46 | J19: =J8*Escenarios!$B$46 | K19: =K8*Escenarios!$B$46 | ... M19: =M8*Escenarios!$B$46
A20: Beneficio antes de impuestos | C20: =PyG!M17 | D20: =D15+D19 | E20: =E15+E19 | F20: =F15+F19 | G20: =G15+G19 | H20: =H15+H19 | I20: =I15+I19 | J20: =J15+J19 | K20: =K15+K19 | ... M20: =M15+M19
